<?xml version="1.0" ?>
<!-- =================================================================================== -->
<!-- |    This document was autogenerated by xacro from temp.urdf.xacro                | -->
<!-- |    EDITING THIS FILE BY HAND IS NOT RECOMMENDED                                 | -->
<!-- =================================================================================== -->
<robot name="arm">
  <material name="white">
    <color rgba="1 1 1 1"/>
  </material>
  <material name="grey">
    <color rgba="0.5 0.5 0.5 1"/>
  </material>
  <material name="red">
    <color rgba="1 0 0 1"/>
  </material>
  <link name="world"/>
  <joint name="base_to_world" type="fixed">
    <child link="base_link"/>
    <parent link="world"/>
    <origin rpy="0 0 0" xyz="0 0 0"/>
  </joint>
  <!--stand-->
  <link name="base_link">
    <visual>
      <geometry>
        <mesh filename="package://arm_description/model/meshes/stand/mounting_plate.stl" scale="0.001 0.001 0.001"/>
      </geometry>
      <origin rpy="1.5708 0 3.1415" xyz="0.06 -0.06 0"/>
      <material name="white"/>
    </visual>
    <collision>
      <geometry>
        <mesh filename="package://arm_description/model/meshes/stand/mounting_plate.dae" scale="0.001 0.001 0.001"/>
      </geometry>
      <origin rpy="1.5708 0 3.1415" xyz="0.06 -0.06 0"/>
      <material name="white"/>
    </collision>
    <inertial>
      <origin xyz="0 0 0"/>
      <mass value="1"/>
      <inertia ixx="0.0001873" ixy="0" ixz="0" iyy="0.000055" iyz="0" izz="0.0002283"/>
    </inertial>
  </link>
  <link name="base_tube">
    <visual>
      <geometry>
        <mesh filename="package://arm_description/model/meshes/stand/base_tube.stl" scale="0.001 0.001 0.001"/>
      </geometry>
      <origin rpy="1.5708 0 3.1415" xyz="0.04 -0.04 0"/>
      <material name="white"/>
    </visual>
    <collision>
      <geometry>
        <mesh filename="package://arm_description/model/meshes/stand/base_tube.dae" scale="0.001 0.001 0.001"/>
      </geometry>
      <origin rpy="1.5708 0 3.1415" xyz="0.04 -0.04 0"/>
      <material name="white"/>
    </collision>
    <inertial>
      <origin xyz="0 0 0"/>
      <mass value="1"/>
      <inertia ixx="0.0001873" ixy="0" ixz="0" iyy="0.000055" iyz="0" izz="0.0002283"/>
    </inertial>
  </link>
  <link name="baseplate">
    <visual>
      <geometry>
        <mesh filename="package://arm_description/model/meshes/stand/baseplate.stl" scale="0.001 0.001 0.001"/>
      </geometry>
      <origin rpy="1.5708 0 3.1415" xyz="0.04 -0.04 0"/>
      <material name="white"/>
    </visual>
    <collision>
      <geometry>
        <mesh filename="package://arm_description/model/meshes/stand/baseplate.dae" scale="0.001 0.001 0.001"/>
      </geometry>
      <origin rpy="1.5708 0 3.1415" xyz="0.04 -0.04 0"/>
      <material name="white"/>
    </collision>
    <inertial>
      <origin xyz="0 0 0"/>
      <mass value="1"/>
      <inertia ixx="0.0001873" ixy="0" ixz="0" iyy="0.000055" iyz="0" izz="0.0002283"/>
    </inertial>
  </link>
  <!--base-->
  <link name="base_pulley">
    <visual>
      <geometry>
        <mesh filename="package://arm_description/model/meshes/base/base_pulley.stl" scale="0.001 0.001 0.001"/>
      </geometry>
      <origin rpy="1.5708 1.5708 3.1415" xyz="0.035 -0.035 0.009"/>
      <material name="white"/>
    </visual>
    <collision>
      <geometry>
        <mesh filename="package://arm_description/model/meshes/base/base_pulley.dae" scale="0.001 0.001 0.001"/>
      </geometry>
      <origin rpy="1.5708 1.5708 3.1415" xyz="0.035 -0.035 0.009"/>
      <material name="white"/>
    </collision>
    <inertial>
      <origin xyz="0 0 0"/>
      <mass value="1"/>
      <inertia ixx="0.0001873" ixy="0" ixz="0" iyy="0.000055" iyz="0" izz="0.0002283"/>
    </inertial>
  </link>
  <link name="base_structure">
    <visual>
      <geometry>
        <mesh filename="package://arm_description/model/meshes/base/base_structure.stl" scale="0.001 0.001 0.001"/>
      </geometry>
      <origin rpy="1.5708 0 -1.5708" xyz="0.0774 0.035 0"/>
      <material name="white"/>
    </visual>
    <collision>
      <geometry>
        <mesh filename="package://arm_description/model/meshes/base/base_structure.dae" scale="0.001 0.001 0.001"/>
      </geometry>
      <origin rpy="1.5708 0 -1.5708" xyz="0.0774 0.035 0"/>
      <material name="white"/>
    </collision>
    <inertial>
      <origin xyz="0 0 0"/>
      <mass value="1"/>
      <inertia ixx="0.0001873" ixy="0" ixz="0" iyy="0.000055" iyz="0" izz="0.0002283"/>
    </inertial>
  </link>
  <link name="base_structure_cover">
    <visual>
      <geometry>
        <mesh filename="package://arm_description/model/meshes/base/base_structure_cover.stl" scale="0.001 0.001 0.001"/>
      </geometry>
      <origin rpy="1.5708 0 0" xyz="-0.0826 -0.02 0"/>
      <material name="white"/>
    </visual>
    <collision>
      <geometry>
        <mesh filename="package://arm_description/model/meshes/base/base_structure_cover.dae" scale="0.001 0.001 0.001"/>
      </geometry>
      <origin rpy="1.5708 0 0" xyz="-0.0826 -0.02 0"/>
      <material name="white"/>
    </collision>
    <inertial>
      <origin xyz="0 0 0"/>
      <mass value="1"/>
      <inertia ixx="0.0001873" ixy="0" ixz="0" iyy="0.000055" iyz="0" izz="0.0002283"/>
    </inertial>
  </link>
  <!--upperarm-->
  <link name="upper_pulley">
    <visual>
      <geometry>
        <mesh filename="package://arm_description/model/meshes/upperarm/j2_pulley.stl" scale="0.001 0.001 0.001"/>
      </geometry>
      <origin rpy="0 0 0" xyz="-0.04 -0.04 0"/>
      <material name="white"/>
    </visual>
    <collision>
      <geometry>
        <mesh filename="package://arm_description/model/meshes/upperarm/j2_pulley.dae" scale="0.001 0.001 0.001"/>
      </geometry>
      <origin rpy="0 0 0" xyz="-0.04 -0.04 0"/>
      <material name="white"/>
    </collision>
    <inertial>
      <origin xyz="0 0 0"/>
      <mass value="1"/>
      <inertia ixx="0.0001873" ixy="0" ixz="0" iyy="0.000055" iyz="0" izz="0.0002283"/>
    </inertial>
  </link>
  <link name="upper_structure">
    <visual>
      <geometry>
        <mesh filename="package://arm_description/model/meshes/upperarm/upper_structure.stl" scale="0.001 0.001 0.001"/>
      </geometry>
      <origin rpy="0 3.1415 0" xyz="0.042 -0.03 0"/>
      <material name="white"/>
    </visual>
    <collision>
      <geometry>
        <mesh filename="package://arm_description/model/meshes/upperarm/upper_structure.dae" scale="0.001 0.001 0.001"/>
      </geometry>
      <origin rpy="0 3.1415 0" xyz="0.042 -0.03 0"/>
      <material name="white"/>
    </collision>
    <inertial>
      <origin xyz="0 0 0"/>
      <mass value="1"/>
      <inertia ixx="0.0001873" ixy="0" ixz="0" iyy="0.000055" iyz="0" izz="0.0002283"/>
    </inertial>
  </link>
  <link name="upper_bearing_mount">
    <visual>
      <geometry>
        <mesh filename="package://arm_description/model/meshes/upperarm/upper_bearing_mount.stl" scale="0.001 0.001 0.001"/>
      </geometry>
      <origin rpy="0 3.1415 0" xyz="0.042 -0.03 -0.00025"/>
      <material name="white"/>
    </visual>
    <collision>
      <geometry>
        <mesh filename="package://arm_description/model/meshes/upperarm/upper_bearing_mount.dae" scale="0.001 0.001 0.001"/>
      </geometry>
      <origin rpy="0 3.1415 0" xyz="0.042 -0.03 -0.00025"/>
      <material name="white"/>
    </collision>
    <inertial>
      <origin xyz="0 0 0"/>
      <mass value="1"/>
      <inertia ixx="0.0001873" ixy="0" ixz="0" iyy="0.000055" iyz="0" izz="0.0002283"/>
    </inertial>
  </link>
  <link name="upper_housing">
    <visual>
      <geometry>
        <mesh filename="package://arm_description/model/meshes/upperarm/upper_housing.stl" scale="0.001 0.001 0.001"/>
      </geometry>
      <origin rpy="0 0 0" xyz="0.028 -0.03 -0.062"/>
      <material name="white"/>
    </visual>
    <collision>
      <geometry>
        <mesh filename="package://arm_description/model/meshes/upperarm/upper_housing.dae" scale="0.001 0.001 0.001"/>
      </geometry>
      <origin rpy="0 0 0" xyz="0.028 -0.03 -0.062"/>
      <material name="white"/>
    </collision>
    <inertial>
      <origin xyz="0 0 0"/>
      <mass value="1"/>
      <inertia ixx="0.0001873" ixy="0" ixz="0" iyy="0.000055" iyz="0" izz="0.0002283"/>
    </inertial>
  </link>
  <!--forearm-->
  <link name="fore_pulley">
    <visual>
      <geometry>
        <mesh filename="package://arm_description/model/meshes/forearm/j3_pulley.stl" scale="0.001 0.001 0.001"/>
      </geometry>
      <origin rpy="0 1.5708 0" xyz="-0.035 -0.035 0.0175"/>
      <material name="white"/>
    </visual>
    <collision>
      <geometry>
        <mesh filename="package://arm_description/model/meshes/forearm/j3_pulley.dae" scale="0.001 0.001 0.001"/>
      </geometry>
      <origin rpy="0 1.5708 0" xyz="-0.035 -0.035 0.0175"/>
      <material name="white"/>
    </collision>
    <inertial>
      <origin xyz="0 0 0"/>
      <mass value="1"/>
      <inertia ixx="0.0001873" ixy="0" ixz="0" iyy="0.000055" iyz="0" izz="0.0002283"/>
    </inertial>
  </link>
  <link name="fore_structure">
    <visual>
      <geometry>
        <mesh filename="package://arm_description/model/meshes/forearm/forearm_structure.stl" scale="0.001 0.001 0.001"/>
      </geometry>
      <origin rpy="3.1415 -1.5708 1.5708" xyz="-0.045 -0.043 0"/>
      <material name="white"/>
    </visual>
    <collision>
      <geometry>
        <mesh filename="package://arm_description/model/meshes/forearm/forearm_structure.dae" scale="0.001 0.001 0.001"/>
      </geometry>
      <origin rpy="3.1415 -1.5708 1.5708" xyz="-0.045 -0.043 0"/>
      <material name="white"/>
    </collision>
    <inertial>
      <origin xyz="0 0 0"/>
      <mass value="1"/>
      <inertia ixx="0.0001873" ixy="0" ixz="0" iyy="0.000055" iyz="0" izz="0.0002283"/>
    </inertial>
  </link>
  <link name="fore_rotation">
    <visual>
      <geometry>
        <mesh filename="package://arm_description/model/meshes/forearm/forearm_rotation.stl" scale="0.001 0.001 0.001"/>
      </geometry>
      <origin rpy="0 0 0" xyz="-0.033 -0.0175 0"/>
      <material name="white"/>
    </visual>
    <collision>
      <geometry>
        <mesh filename="package://arm_description/model/meshes/forearm/forearm_rotation.dae" scale="0.001 0.001 0.001"/>
      </geometry>
      <origin rpy="0 0 0" xyz="-0.033 -0.0175 0"/>
      <material name="white"/>
    </collision>
    <inertial>
      <origin xyz="0 0 0"/>
      <mass value="1"/>
      <inertia ixx="0.0001873" ixy="0" ixz="0" iyy="0.000055" iyz="0" izz="0.0002283"/>
    </inertial>
  </link>
  <link name="j5_bearing_adapter_1">
    <visual>
      <geometry>
        <mesh filename="package://arm_description/model/meshes/forearm/j5_bearing_adapter.stl" scale="0.001 0.001 0.001"/>
      </geometry>
      <origin rpy="1.5708 1.5708 0" xyz="-0.023 0.011 0.10525"/>
      <material name="white"/>
    </visual>
    <collision>
      <geometry>
        <mesh filename="package://arm_description/model/meshes/forearm/j5_bearing_adapter.dae" scale="0.001 0.001 0.001"/>
      </geometry>
      <origin rpy="1.5708 1.5708 0" xyz="-0.023 0.011 0.10525"/>
      <material name="white"/>
    </collision>
    <inertial>
      <origin xyz="0 0 0"/>
      <mass value="1"/>
      <inertia ixx="0.0001873" ixy="0" ixz="0" iyy="0.000055" iyz="0" izz="0.0002283"/>
    </inertial>
  </link>
  <link name="j5_bearing_adapter_2">
    <visual>
      <geometry>
        <mesh filename="package://arm_description/model/meshes/forearm/j5_bearing_adapter.stl" scale="0.001 0.001 0.001"/>
      </geometry>
      <origin rpy="-1.5708 1.5708 0" xyz="0.023 -0.011 0.09525"/>
      <material name="white"/>
    </visual>
    <collision>
      <geometry>
        <mesh filename="package://arm_description/model/meshes/forearm/j5_bearing_adapter.dae" scale="0.001 0.001 0.001"/>
      </geometry>
      <origin rpy="-1.5708 1.5708 0" xyz="0.023 -0.011 0.09525"/>
      <material name="white"/>
    </collision>
    <inertial>
      <origin xyz="0 0 0"/>
      <mass value="1"/>
      <inertia ixx="0.0001873" ixy="0" ixz="0" iyy="0.000055" iyz="0" izz="0.0002283"/>
    </inertial>
  </link>
  <link name="j6_housing">
    <visual>
      <geometry>
        <mesh filename="package://arm_description/model/meshes/forearm/j6_housing.stl" scale="0.001 0.001 0.001"/>
      </geometry>
      <origin rpy="0 0 0" xyz="-0.01385 -0.01085 -0.02"/>
      <material name="white"/>
    </visual>
    <collision>
      <geometry>
        <mesh filename="package://arm_description/model/meshes/forearm/j6_housing.dae" scale="0.001 0.001 0.001"/>
      </geometry>
      <origin rpy="0 0 0" xyz="-0.01385 -0.01085 -0.02"/>
      <material name="white"/>
    </collision>
    <inertial>
      <origin xyz="0 0 0"/>
      <mass value="1"/>
      <inertia ixx="0.0001873" ixy="0" ixz="0" iyy="0.000055" iyz="0" izz="0.0002283"/>
    </inertial>
  </link>
  <!--end effector-->
  <link name="j6_nema8">
    <visual>
      <geometry>
        <mesh filename="package://arm_description/model/meshes/forearm/j6_nema8.stl" scale="0.001 0.001 0.001"/>
      </geometry>
      <origin rpy="0 0 0" xyz="0 0 0"/>
      <material name="red"/>
    </visual>
    <collision>
      <geometry>
        <mesh filename="package://arm_description/model/meshes/forearm/j6_nema8.dae" scale="0.001 0.001 0.001"/>
      </geometry>
      <origin rpy="0 0 0" xyz="0 0 0"/>
      <material name="red"/>
    </collision>
    <inertial>
      <origin xyz="0 0 0"/>
      <mass value="1"/>
      <inertia ixx="0.0001873" ixy="0" ixz="0" iyy="0.000055" iyz="0" izz="0.0002283"/>
    </inertial>
  </link>
  <!--JOINTS-->
  <!--stand joints-->
  <joint name="stand_link_tube_joint" type="fixed">
    <parent link="base_link"/>
    <child link="base_tube"/>
    <origin rpy="0 0 0" xyz="0 0 0.02"/>
  </joint>
  <joint name="stand_tube_baseplate_joint" type="fixed">
    <parent link="base_tube"/>
    <child link="baseplate"/>
    <origin rpy="0 0 0" xyz="0 0 0.048"/>
  </joint>
  <!--base joints-->
  <!--J1-->
  <joint name="J1" type="continuous">
    <parent link="baseplate"/>
    <child link="base_pulley"/>
    <origin rpy="0 0 0" xyz="0 0 0.016"/>
    <axis xyz="0 0 1"/>
  </joint>
  <joint name="base_pulley_structure_joint" type="fixed">
    <parent link="base_pulley"/>
    <child link="base_structure"/>
    <origin rpy="0 0 0" xyz="0 0 0.009"/>
  </joint>
  <joint name="base_structure_cover_joint" type="fixed">
    <parent link="base_structure"/>
    <child link="base_structure_cover"/>
    <origin rpy="0 0 0" xyz="0 0 0"/>
  </joint>
  <!--upperarm joints-->
  <!--J2-->
  <joint name="J2" type="revolute">
    <parent link="base_structure"/>
    <child link="upper_pulley"/>
    <origin rpy="1.5708 0 3.1415" xyz="0.037 -0.0337 0.04"/>
    <limit effort="10" lower="-0.349" upper="1.5708" velocity="3"/>
    <axis xyz="0 0 1"/>
  </joint>
  <joint name="upper_pulley_structure" type="fixed">
    <parent link="upper_pulley"/>
    <child link="upper_structure"/>
    <origin rpy="0 0 0" xyz="0 0 0"/>
  </joint>
  <joint name="upper_structure_mount" type="fixed">
    <parent link="upper_structure"/>
    <child link="upper_bearing_mount"/>
    <origin rpy="0 1.5708 0" xyz="0.031 0.03 0.042"/>
  </joint>
  <joint name="upper_mount_housing" type="fixed">
    <parent link="upper_bearing_mount"/>
    <child link="upper_housing"/>
    <origin rpy="0 0 0" xyz="0 0 0"/>
  </joint>
  <!--forearm joints-->
  <!--J3-->
  <joint name="J3" type="revolute">
    <parent link="upper_structure"/>
    <child link="fore_pulley"/>
    <origin rpy="0 0 1.5708" xyz="0.0 0.16 0.0"/>
    <limit effort="10" lower="-3.1415" upper="1.5708" velocity="3"/>
    <axis xyz="0 0 1"/>
  </joint>
  <joint name="fore_pully_structure_joint" type="fixed">
    <parent link="fore_pulley"/>
    <child link="fore_structure"/>
    <origin rpy="0 0 0" xyz="0 0 0.01"/>
  </joint>
  <!--J4-->
  <joint name="J4" type="revolute">
    <parent link="fore_structure"/>
    <child link="fore_rotation"/>
    <origin rpy="0 1.5708 1.5708" xyz="0.015 0.035 0.0245"/>
    <limit effort="10" lower="-3.1415" upper="1.5708" velocity="3"/>
    <axis xyz="0 0 1"/>
  </joint>
  <joint name="fore_rotation_bearing_1" type="fixed">
    <parent link="fore_rotation"/>
    <child link="j5_bearing_adapter_1"/>
    <origin rpy="0 0 0" xyz="0 0 0.01"/>
  </joint>
  <joint name="fore_rotation_bearing_2" type="fixed">
    <parent link="fore_rotation"/>
    <child link="j5_bearing_adapter_2"/>
    <origin rpy="0 0 0" xyz="0 0 0.02"/>
  </joint>
  <!--J5-->
  <joint name="J5" type="revolute">
    <parent link="j5_bearing_adapter_1"/>
    <child link="j6_housing"/>
    <origin rpy="0 0 0" xyz="0 0 0.0925"/>
    <limit effort="10" lower="-3.1415" upper="1.5708" velocity="3"/>
    <axis xyz="1 0 0"/>
  </joint>
  <!--end effector joints-->
  <joint name="end_housing_nema8" type="fixed">
    <parent link="j6_housing"/>
    <child link="j6_nema8"/>
    <origin rpy="0 0 0" xyz="0 0 0.0078"/>
  </joint>
  <!--include relevant to gazebo simulation-->
  <gazebo>
    <plugin filename="libgazebo_ros2_control.so" name="ros2_control">
      <ros>
        <namespace>/</namespace>
        <remapping>joint_states:=/joint_states</remapping>
      </ros>
      <robotSimType>gazebo_ros2_control/DefaultRobotHWSim</robotSimType>
    </plugin>
  </gazebo>
</robot>
